/*
 *** MADE BY MITHION'S .SCHEMATIC TO JAVA CONVERTING TOOL v1.6 ***
 */

package net.divinerpg.overworld.gen;
import java.util.Random;

import net.divinerpg.helper.block.IceikaBlockHelper;
import net.minecraft.block.Block;
import net.minecraft.world.World;
import net.minecraft.world.gen.feature.WorldGenerator;

public class WorldGenIceikaTree extends WorldGenerator
{
    protected int[] GetValidSpawnBlocks() {
        return new int[] {
                IceikaBlockHelper.IceGrass.blockID
        };
    }

    public boolean LocationIsValidSpawn(World world, int i, int j, int k){
        int distanceToAir = 0;
        int checkID = world.getBlockId(i, j, k);

        while (checkID != 0){
            distanceToAir++;
            checkID = world.getBlockId(i, j + distanceToAir, k);
        }

        if (distanceToAir > 3)
            return false;
        j += distanceToAir - 1;

        int blockID = world.getBlockId(i, j, k);
        int blockIDAbove = world.getBlockId(i, j+1, k);
        int blockIDBelow = world.getBlockId(i, j-1, k);
        for (int x : GetValidSpawnBlocks()){
            if (blockIDAbove != 0)
                return false;
            if (blockID == x)
                return true;
            else if (blockID == Block.snow.blockID && blockIDBelow == x)
                return true;
        }
        return false;
    }

    public WorldGenIceikaTree() { }

    @Override
    public boolean generate(World world, Random rand, int i, int j, int k) {
        //check that each corner is one of the valid spawn blocks
        if(!LocationIsValidSpawn(world, i, j, k) || !LocationIsValidSpawn(world, i + 5, j, k) || !LocationIsValidSpawn(world, i + 5, j, k + 5) || !LocationIsValidSpawn(world, i, j, k + 5))
            return false;

        world.setBlock(i + 0, j + 0, k + 0, IceikaBlockHelper.IceGrass.blockID);
        world.setBlock(i + 0, j + 0, k + 1, IceikaBlockHelper.IceGrass.blockID);
        world.setBlock(i + 0, j + 0, k + 2, IceikaBlockHelper.IceGrass.blockID);
        world.setBlock(i + 0, j + 0, k + 3, IceikaBlockHelper.IceGrass.blockID);
        world.setBlock(i + 0, j + 0, k + 4, IceikaBlockHelper.IceGrass.blockID);
        world.setBlock(i + 0, j + 0, k + 5, IceikaBlockHelper.IceGrass.blockID);
        world.setBlock(i + 0, j + 1, k + 0, 0);
        world.setBlock(i + 0, j + 1, k + 1, 0);
        world.setBlock(i + 0, j + 1, k + 2, 0);
        world.setBlock(i + 0, j + 1, k + 3, 0);
        world.setBlock(i + 0, j + 1, k + 4, 0);
        world.setBlock(i + 0, j + 1, k + 5, 0);
        world.setBlock(i + 0, j + 2, k + 0, 0);
        world.setBlock(i + 0, j + 2, k + 1, 0);
        world.setBlock(i + 0, j + 2, k + 2, 0);
        world.setBlock(i + 0, j + 2, k + 3, 0);
        world.setBlock(i + 0, j + 2, k + 4, 0);
        world.setBlock(i + 0, j + 2, k + 5, 0);
        world.setBlock(i + 0, j + 3, k + 0, 0);
        world.setBlock(i + 0, j + 3, k + 1, 0);
        world.setBlock(i + 0, j + 3, k + 2, 0);
        world.setBlock(i + 0, j + 3, k + 3, 0);
        world.setBlock(i + 0, j + 3, k + 4, 0);
        world.setBlock(i + 0, j + 3, k + 5, 0);
        world.setBlock(i + 0, j + 4, k + 0, IceikaBlockHelper.IceLeaves.blockID);
        world.setBlock(i + 0, j + 4, k + 1, IceikaBlockHelper.IceLeaves.blockID);
        world.setBlock(i + 0, j + 4, k + 2, IceikaBlockHelper.IceLeaves.blockID);
        world.setBlock(i + 0, j + 4, k + 3, IceikaBlockHelper.IceLeaves.blockID);
        world.setBlock(i + 0, j + 4, k + 4, IceikaBlockHelper.IceLeaves.blockID);
        world.setBlock(i + 0, j + 4, k + 5, IceikaBlockHelper.IceLeaves.blockID);
        world.setBlock(i + 0, j + 5, k + 0, 0);
        world.setBlock(i + 0, j + 5, k + 1, 0);
        world.setBlock(i + 0, j + 5, k + 2, 0);
        world.setBlock(i + 0, j + 5, k + 3, 0);
        world.setBlock(i + 0, j + 5, k + 4, 0);
        world.setBlock(i + 0, j + 5, k + 5, 0);
        world.setBlock(i + 0, j + 6, k + 0, 0);
        world.setBlock(i + 0, j + 6, k + 1, 0);
        world.setBlock(i + 0, j + 6, k + 2, 0);
        world.setBlock(i + 0, j + 6, k + 3, 0);
        world.setBlock(i + 0, j + 6, k + 4, 0);
        world.setBlock(i + 0, j + 6, k + 5, 0);
        world.setBlock(i + 0, j + 7, k + 0, IceikaBlockHelper.IceLeaves.blockID);
        world.setBlock(i + 0, j + 7, k + 1, IceikaBlockHelper.IceLeaves.blockID);
        world.setBlock(i + 0, j + 7, k + 2, IceikaBlockHelper.IceLeaves.blockID);
        world.setBlock(i + 0, j + 7, k + 3, IceikaBlockHelper.IceLeaves.blockID);
        world.setBlock(i + 0, j + 7, k + 4, IceikaBlockHelper.IceLeaves.blockID);
        world.setBlock(i + 0, j + 7, k + 5, IceikaBlockHelper.IceLeaves.blockID);
        world.setBlock(i + 0, j + 8, k + 0, 0);
        world.setBlock(i + 0, j + 8, k + 1, 0);
        world.setBlock(i + 0, j + 8, k + 2, 0);
        world.setBlock(i + 0, j + 8, k + 3, 0);
        world.setBlock(i + 0, j + 8, k + 4, 0);
        world.setBlock(i + 0, j + 8, k + 5, 0);
        world.setBlock(i + 0, j + 9, k + 0, 0);
        world.setBlock(i + 0, j + 9, k + 1, 0);
        world.setBlock(i + 0, j + 9, k + 2, 0);
        world.setBlock(i + 0, j + 9, k + 3, 0);
        world.setBlock(i + 0, j + 9, k + 4, 0);
        world.setBlock(i + 0, j + 9, k + 5, 0);
        world.setBlock(i + 0, j + 10, k + 0, IceikaBlockHelper.IceLeaves.blockID);
        world.setBlock(i + 0, j + 10, k + 1, IceikaBlockHelper.IceLeaves.blockID);
        world.setBlock(i + 0, j + 10, k + 2, IceikaBlockHelper.IceLeaves.blockID);
        world.setBlock(i + 0, j + 10, k + 3, IceikaBlockHelper.IceLeaves.blockID);
        world.setBlock(i + 0, j + 10, k + 4, IceikaBlockHelper.IceLeaves.blockID);
        world.setBlock(i + 0, j + 10, k + 5, IceikaBlockHelper.IceLeaves.blockID);
        world.setBlock(i + 0, j + 11, k + 0, 0);
        world.setBlock(i + 0, j + 11, k + 1, 0);
        world.setBlock(i + 0, j + 11, k + 2, 0);
        world.setBlock(i + 0, j + 11, k + 3, 0);
        world.setBlock(i + 0, j + 11, k + 4, 0);
        world.setBlock(i + 0, j + 11, k + 5, 0);
        world.setBlock(i + 0, j + 12, k + 0, 0);
        world.setBlock(i + 0, j + 12, k + 1, 0);
        world.setBlock(i + 0, j + 12, k + 2, 0);
        world.setBlock(i + 0, j + 12, k + 3, 0);
        world.setBlock(i + 0, j + 12, k + 4, 0);
        world.setBlock(i + 0, j + 12, k + 5, 0);
        world.setBlock(i + 0, j + 13, k + 0, IceikaBlockHelper.IceLeaves.blockID);
        world.setBlock(i + 0, j + 13, k + 1, IceikaBlockHelper.IceLeaves.blockID);
        world.setBlock(i + 0, j + 13, k + 2, IceikaBlockHelper.IceLeaves.blockID);
        world.setBlock(i + 0, j + 13, k + 3, IceikaBlockHelper.IceLeaves.blockID);
        world.setBlock(i + 0, j + 13, k + 4, IceikaBlockHelper.IceLeaves.blockID);
        world.setBlock(i + 0, j + 13, k + 5, IceikaBlockHelper.IceLeaves.blockID);
        world.setBlock(i + 0, j + 14, k + 0, 0);
        world.setBlock(i + 0, j + 14, k + 1, 0);
        world.setBlock(i + 0, j + 14, k + 2, 0);
        world.setBlock(i + 0, j + 14, k + 3, 0);
        world.setBlock(i + 0, j + 14, k + 4, 0);
        world.setBlock(i + 0, j + 14, k + 5, 0);
        world.setBlock(i + 0, j + 15, k + 0, 0);
        world.setBlock(i + 0, j + 15, k + 1, 0);
        world.setBlock(i + 0, j + 15, k + 2, 0);
        world.setBlock(i + 0, j + 15, k + 3, 0);
        world.setBlock(i + 0, j + 15, k + 4, 0);
        world.setBlock(i + 0, j + 15, k + 5, 0);
        world.setBlock(i + 0, j + 16, k + 0, IceikaBlockHelper.IceLeaves.blockID);
        world.setBlock(i + 0, j + 16, k + 1, IceikaBlockHelper.IceLeaves.blockID);
        world.setBlock(i + 0, j + 16, k + 2, IceikaBlockHelper.IceLeaves.blockID);
        world.setBlock(i + 0, j + 16, k + 3, IceikaBlockHelper.IceLeaves.blockID);
        world.setBlock(i + 0, j + 16, k + 4, IceikaBlockHelper.IceLeaves.blockID);
        world.setBlock(i + 0, j + 16, k + 5, IceikaBlockHelper.IceLeaves.blockID);
        world.setBlock(i + 0, j + 17, k + 0, 0);
        world.setBlock(i + 0, j + 17, k + 1, 0);
        world.setBlock(i + 0, j + 17, k + 2, 0);
        world.setBlock(i + 0, j + 17, k + 3, 0);
        world.setBlock(i + 0, j + 17, k + 4, 0);
        world.setBlock(i + 0, j + 17, k + 5, 0);
        world.setBlock(i + 0, j + 18, k + 0, 0);
        world.setBlock(i + 0, j + 18, k + 1, 0);
        world.setBlock(i + 0, j + 18, k + 2, 0);
        world.setBlock(i + 0, j + 18, k + 3, 0);
        world.setBlock(i + 0, j + 18, k + 4, 0);
        world.setBlock(i + 0, j + 18, k + 5, 0);
        world.setBlock(i + 0, j + 19, k + 0, IceikaBlockHelper.IceLeaves.blockID);
        world.setBlock(i + 0, j + 19, k + 1, IceikaBlockHelper.IceLeaves.blockID);
        world.setBlock(i + 0, j + 19, k + 2, IceikaBlockHelper.IceLeaves.blockID);
        world.setBlock(i + 0, j + 19, k + 3, IceikaBlockHelper.IceLeaves.blockID);
        world.setBlock(i + 0, j + 19, k + 4, IceikaBlockHelper.IceLeaves.blockID);
        world.setBlock(i + 0, j + 19, k + 5, IceikaBlockHelper.IceLeaves.blockID);
        world.setBlock(i + 0, j + 20, k + 0, 0);
        world.setBlock(i + 0, j + 20, k + 1, 0);
        world.setBlock(i + 0, j + 20, k + 2, 0);
        world.setBlock(i + 0, j + 20, k + 3, 0);
        world.setBlock(i + 0, j + 20, k + 4, 0);
        world.setBlock(i + 0, j + 20, k + 5, 0);
        world.setBlock(i + 0, j + 21, k + 0, 0);
        world.setBlock(i + 0, j + 21, k + 1, 0);
        world.setBlock(i + 0, j + 21, k + 2, 0);
        world.setBlock(i + 0, j + 21, k + 3, 0);
        world.setBlock(i + 0, j + 21, k + 4, 0);
        world.setBlock(i + 0, j + 21, k + 5, 0);
        world.setBlock(i + 0, j + 22, k + 0, IceikaBlockHelper.IceLeaves.blockID);
        world.setBlock(i + 0, j + 22, k + 1, IceikaBlockHelper.IceLeaves.blockID);
        world.setBlock(i + 0, j + 22, k + 2, IceikaBlockHelper.IceLeaves.blockID);
        world.setBlock(i + 0, j + 22, k + 3, IceikaBlockHelper.IceLeaves.blockID);
        world.setBlock(i + 0, j + 22, k + 4, IceikaBlockHelper.IceLeaves.blockID);
        world.setBlock(i + 0, j + 22, k + 5, IceikaBlockHelper.IceLeaves.blockID);
        world.setBlock(i + 0, j + 23, k + 0, 0);
        world.setBlock(i + 0, j + 23, k + 1, 0);
        world.setBlock(i + 0, j + 23, k + 2, 0);
        world.setBlock(i + 0, j + 23, k + 3, 0);
        world.setBlock(i + 0, j + 23, k + 4, 0);
        world.setBlock(i + 0, j + 23, k + 5, 0);
        world.setBlock(i + 0, j + 24, k + 0, IceikaBlockHelper.IceLeaves.blockID);
        world.setBlock(i + 0, j + 24, k + 1, IceikaBlockHelper.IceLeaves.blockID);
        world.setBlock(i + 0, j + 24, k + 2, IceikaBlockHelper.IceLeaves.blockID);
        world.setBlock(i + 0, j + 24, k + 3, IceikaBlockHelper.IceLeaves.blockID);
        world.setBlock(i + 0, j + 24, k + 4, IceikaBlockHelper.IceLeaves.blockID);
        world.setBlock(i + 0, j + 24, k + 5, IceikaBlockHelper.IceLeaves.blockID);
        world.setBlock(i + 0, j + 25, k + 0, 0);
        world.setBlock(i + 0, j + 25, k + 1, 0);
        world.setBlock(i + 0, j + 25, k + 2, 0);
        world.setBlock(i + 0, j + 25, k + 3, 0);
        world.setBlock(i + 0, j + 25, k + 4, 0);
        world.setBlock(i + 0, j + 25, k + 5, 0);
        world.setBlock(i + 0, j + 26, k + 0, 0);
        world.setBlock(i + 0, j + 26, k + 1, 0);
        world.setBlock(i + 0, j + 26, k + 2, 0);
        world.setBlock(i + 0, j + 26, k + 3, 0);
        world.setBlock(i + 0, j + 26, k + 4, 0);
        world.setBlock(i + 0, j + 26, k + 5, 0);
        world.setBlock(i + 1, j + 0, k + 0, IceikaBlockHelper.IceGrass.blockID);
        world.setBlock(i + 1, j + 0, k + 1, IceikaBlockHelper.IceGrass.blockID);
        world.setBlock(i + 1, j + 0, k + 2, IceikaBlockHelper.IceGrass.blockID);
        world.setBlock(i + 1, j + 0, k + 3, IceikaBlockHelper.IceGrass.blockID);
        world.setBlock(i + 1, j + 0, k + 4, IceikaBlockHelper.IceGrass.blockID);
        world.setBlock(i + 1, j + 0, k + 5, IceikaBlockHelper.IceGrass.blockID);
        world.setBlock(i + 1, j + 1, k + 0, 0);
        world.setBlock(i + 1, j + 1, k + 1, 0);
        world.setBlock(i + 1, j + 1, k + 2, 0);
        world.setBlock(i + 1, j + 1, k + 3, 0);
        world.setBlock(i + 1, j + 1, k + 4, 0);
        world.setBlock(i + 1, j + 1, k + 5, 0);
        world.setBlock(i + 1, j + 2, k + 0, 0);
        world.setBlock(i + 1, j + 2, k + 1, 0);
        world.setBlock(i + 1, j + 2, k + 2, 0);
        world.setBlock(i + 1, j + 2, k + 3, 0);
        world.setBlock(i + 1, j + 2, k + 4, 0);
        world.setBlock(i + 1, j + 2, k + 5, 0);
        world.setBlock(i + 1, j + 3, k + 0, 0);
        world.setBlock(i + 1, j + 3, k + 1, 0);
        world.setBlock(i + 1, j + 3, k + 2, 0);
        world.setBlock(i + 1, j + 3, k + 3, 0);
        world.setBlock(i + 1, j + 3, k + 4, 0);
        world.setBlock(i + 1, j + 3, k + 5, 0);
        world.setBlock(i + 1, j + 4, k + 0, IceikaBlockHelper.IceLeaves.blockID);
        world.setBlock(i + 1, j + 4, k + 1, IceikaBlockHelper.IceLeaves.blockID);
        world.setBlock(i + 1, j + 4, k + 2, IceikaBlockHelper.IceLeaves.blockID);
        world.setBlock(i + 1, j + 4, k + 3, IceikaBlockHelper.IceLeaves.blockID);
        world.setBlock(i + 1, j + 4, k + 4, IceikaBlockHelper.IceLeaves.blockID);
        world.setBlock(i + 1, j + 4, k + 5, IceikaBlockHelper.IceLeaves.blockID);
        world.setBlock(i + 1, j + 5, k + 0, 0);
        world.setBlock(i + 1, j + 5, k + 1, IceikaBlockHelper.IceLeaves.blockID);
        world.setBlock(i + 1, j + 5, k + 2, IceikaBlockHelper.IceLeaves.blockID);
        world.setBlock(i + 1, j + 5, k + 3, IceikaBlockHelper.IceLeaves.blockID);
        world.setBlock(i + 1, j + 5, k + 4, IceikaBlockHelper.IceLeaves.blockID);
        world.setBlock(i + 1, j + 5, k + 5, 0);
        world.setBlock(i + 1, j + 6, k + 0, 0);
        world.setBlock(i + 1, j + 6, k + 1, 0);
        world.setBlock(i + 1, j + 6, k + 2, 0);
        world.setBlock(i + 1, j + 6, k + 3, 0);
        world.setBlock(i + 1, j + 6, k + 4, 0);
        world.setBlock(i + 1, j + 6, k + 5, 0);
        world.setBlock(i + 1, j + 7, k + 0, IceikaBlockHelper.IceLeaves.blockID);
        world.setBlock(i + 1, j + 7, k + 1, IceikaBlockHelper.IceLeaves.blockID);
        world.setBlock(i + 1, j + 7, k + 2, IceikaBlockHelper.IceLeaves.blockID);
        world.setBlock(i + 1, j + 7, k + 3, IceikaBlockHelper.IceLeaves.blockID);
        world.setBlock(i + 1, j + 7, k + 4, IceikaBlockHelper.IceLeaves.blockID);
        world.setBlock(i + 1, j + 7, k + 5, IceikaBlockHelper.IceLeaves.blockID);
        world.setBlock(i + 1, j + 8, k + 0, 0);
        world.setBlock(i + 1, j + 8, k + 1, IceikaBlockHelper.IceLeaves.blockID);
        world.setBlock(i + 1, j + 8, k + 2, IceikaBlockHelper.IceLeaves.blockID);
        world.setBlock(i + 1, j + 8, k + 3, IceikaBlockHelper.IceLeaves.blockID);
        world.setBlock(i + 1, j + 8, k + 4, IceikaBlockHelper.IceLeaves.blockID);
        world.setBlock(i + 1, j + 8, k + 5, 0);
        world.setBlock(i + 1, j + 9, k + 0, 0);
        world.setBlock(i + 1, j + 9, k + 1, 0);
        world.setBlock(i + 1, j + 9, k + 2, 0);
        world.setBlock(i + 1, j + 9, k + 3, 0);
        world.setBlock(i + 1, j + 9, k + 4, 0);
        world.setBlock(i + 1, j + 9, k + 5, 0);
        world.setBlock(i + 1, j + 10, k + 0, IceikaBlockHelper.IceLeaves.blockID);
        world.setBlock(i + 1, j + 10, k + 1, IceikaBlockHelper.IceLeaves.blockID);
        world.setBlock(i + 1, j + 10, k + 2, IceikaBlockHelper.IceLeaves.blockID);
        world.setBlock(i + 1, j + 10, k + 3, IceikaBlockHelper.IceLeaves.blockID);
        world.setBlock(i + 1, j + 10, k + 4, IceikaBlockHelper.IceLeaves.blockID);
        world.setBlock(i + 1, j + 10, k + 5, IceikaBlockHelper.IceLeaves.blockID);
        world.setBlock(i + 1, j + 11, k + 0, 0);
        world.setBlock(i + 1, j + 11, k + 1, IceikaBlockHelper.IceLeaves.blockID);
        world.setBlock(i + 1, j + 11, k + 2, IceikaBlockHelper.IceLeaves.blockID);
        world.setBlock(i + 1, j + 11, k + 3, IceikaBlockHelper.IceLeaves.blockID);
        world.setBlock(i + 1, j + 11, k + 4, IceikaBlockHelper.IceLeaves.blockID);
        world.setBlock(i + 1, j + 11, k + 5, 0);
        world.setBlock(i + 1, j + 12, k + 0, 0);
        world.setBlock(i + 1, j + 12, k + 1, 0);
        world.setBlock(i + 1, j + 12, k + 2, 0);
        world.setBlock(i + 1, j + 12, k + 3, 0);
        world.setBlock(i + 1, j + 12, k + 4, 0);
        world.setBlock(i + 1, j + 12, k + 5, 0);
        world.setBlock(i + 1, j + 13, k + 0, IceikaBlockHelper.IceLeaves.blockID);
        world.setBlock(i + 1, j + 13, k + 1, IceikaBlockHelper.IceLeaves.blockID);
        world.setBlock(i + 1, j + 13, k + 2, IceikaBlockHelper.IceLeaves.blockID);
        world.setBlock(i + 1, j + 13, k + 3, IceikaBlockHelper.IceLeaves.blockID);
        world.setBlock(i + 1, j + 13, k + 4, IceikaBlockHelper.IceLeaves.blockID);
        world.setBlock(i + 1, j + 13, k + 5, IceikaBlockHelper.IceLeaves.blockID);
        world.setBlock(i + 1, j + 14, k + 0, 0);
        world.setBlock(i + 1, j + 14, k + 1, IceikaBlockHelper.IceLeaves.blockID);
        world.setBlock(i + 1, j + 14, k + 2, IceikaBlockHelper.IceLeaves.blockID);
        world.setBlock(i + 1, j + 14, k + 3, IceikaBlockHelper.IceLeaves.blockID);
        world.setBlock(i + 1, j + 14, k + 4, IceikaBlockHelper.IceLeaves.blockID);
        world.setBlock(i + 1, j + 14, k + 5, 0);
        world.setBlock(i + 1, j + 15, k + 0, 0);
        world.setBlock(i + 1, j + 15, k + 1, 0);
        world.setBlock(i + 1, j + 15, k + 2, 0);
        world.setBlock(i + 1, j + 15, k + 3, 0);
        world.setBlock(i + 1, j + 15, k + 4, 0);
        world.setBlock(i + 1, j + 15, k + 5, 0);
        world.setBlock(i + 1, j + 16, k + 0, IceikaBlockHelper.IceLeaves.blockID);
        world.setBlock(i + 1, j + 16, k + 1, IceikaBlockHelper.IceLeaves.blockID);
        world.setBlock(i + 1, j + 16, k + 2, IceikaBlockHelper.IceLeaves.blockID);
        world.setBlock(i + 1, j + 16, k + 3, IceikaBlockHelper.IceLeaves.blockID);
        world.setBlock(i + 1, j + 16, k + 4, IceikaBlockHelper.IceLeaves.blockID);
        world.setBlock(i + 1, j + 16, k + 5, IceikaBlockHelper.IceLeaves.blockID);
        world.setBlock(i + 1, j + 17, k + 0, 0);
        world.setBlock(i + 1, j + 17, k + 1, IceikaBlockHelper.IceLeaves.blockID);
        world.setBlock(i + 1, j + 17, k + 2, IceikaBlockHelper.IceLeaves.blockID);
        world.setBlock(i + 1, j + 17, k + 3, IceikaBlockHelper.IceLeaves.blockID);
        world.setBlock(i + 1, j + 17, k + 4, IceikaBlockHelper.IceLeaves.blockID);
        world.setBlock(i + 1, j + 17, k + 5, 0);
        world.setBlock(i + 1, j + 18, k + 0, 0);
        world.setBlock(i + 1, j + 18, k + 1, 0);
        world.setBlock(i + 1, j + 18, k + 2, 0);
        world.setBlock(i + 1, j + 18, k + 3, 0);
        world.setBlock(i + 1, j + 18, k + 4, 0);
        world.setBlock(i + 1, j + 18, k + 5, 0);
        world.setBlock(i + 1, j + 19, k + 0, IceikaBlockHelper.IceLeaves.blockID);
        world.setBlock(i + 1, j + 19, k + 1, IceikaBlockHelper.IceLeaves.blockID);
        world.setBlock(i + 1, j + 19, k + 2, IceikaBlockHelper.IceLeaves.blockID);
        world.setBlock(i + 1, j + 19, k + 3, IceikaBlockHelper.IceLeaves.blockID);
        world.setBlock(i + 1, j + 19, k + 4, IceikaBlockHelper.IceLeaves.blockID);
        world.setBlock(i + 1, j + 19, k + 5, IceikaBlockHelper.IceLeaves.blockID);
        world.setBlock(i + 1, j + 20, k + 0, 0);
        world.setBlock(i + 1, j + 20, k + 1, IceikaBlockHelper.IceLeaves.blockID);
        world.setBlock(i + 1, j + 20, k + 2, IceikaBlockHelper.IceLeaves.blockID);
        world.setBlock(i + 1, j + 20, k + 3, IceikaBlockHelper.IceLeaves.blockID);
        world.setBlock(i + 1, j + 20, k + 4, IceikaBlockHelper.IceLeaves.blockID);
        world.setBlock(i + 1, j + 20, k + 5, 0);
        world.setBlock(i + 1, j + 21, k + 0, 0);
        world.setBlock(i + 1, j + 21, k + 1, 0);
        world.setBlock(i + 1, j + 21, k + 2, 0);
        world.setBlock(i + 1, j + 21, k + 3, 0);
        world.setBlock(i + 1, j + 21, k + 4, 0);
        world.setBlock(i + 1, j + 21, k + 5, 0);
        world.setBlock(i + 1, j + 22, k + 0, IceikaBlockHelper.IceLeaves.blockID);
        world.setBlock(i + 1, j + 22, k + 1, IceikaBlockHelper.IceLeaves.blockID);
        world.setBlock(i + 1, j + 22, k + 2, IceikaBlockHelper.IceLeaves.blockID);
        world.setBlock(i + 1, j + 22, k + 3, IceikaBlockHelper.IceLeaves.blockID);
        world.setBlock(i + 1, j + 22, k + 4, IceikaBlockHelper.IceLeaves.blockID);
        world.setBlock(i + 1, j + 22, k + 5, IceikaBlockHelper.IceLeaves.blockID);
        world.setBlock(i + 1, j + 23, k + 0, 0);
        world.setBlock(i + 1, j + 23, k + 1, 0);
        world.setBlock(i + 1, j + 23, k + 2, 0);
        world.setBlock(i + 1, j + 23, k + 3, 0);
        world.setBlock(i + 1, j + 23, k + 4, 0);
        world.setBlock(i + 1, j + 23, k + 5, 0);
        world.setBlock(i + 1, j + 24, k + 0, IceikaBlockHelper.IceLeaves.blockID);
        world.setBlock(i + 1, j + 24, k + 1, IceikaBlockHelper.IceLeaves.blockID);
        world.setBlock(i + 1, j + 24, k + 2, IceikaBlockHelper.IceLeaves.blockID);
        world.setBlock(i + 1, j + 24, k + 3, IceikaBlockHelper.IceLeaves.blockID);
        world.setBlock(i + 1, j + 24, k + 4, IceikaBlockHelper.IceLeaves.blockID);
        world.setBlock(i + 1, j + 24, k + 5, IceikaBlockHelper.IceLeaves.blockID);
        world.setBlock(i + 1, j + 25, k + 0, 0);
        world.setBlock(i + 1, j + 25, k + 1, IceikaBlockHelper.IceLeaves.blockID);
        world.setBlock(i + 1, j + 25, k + 2, IceikaBlockHelper.IceLeaves.blockID);
        world.setBlock(i + 1, j + 25, k + 3, IceikaBlockHelper.IceLeaves.blockID);
        world.setBlock(i + 1, j + 25, k + 4, IceikaBlockHelper.IceLeaves.blockID);
        world.setBlock(i + 1, j + 25, k + 5, 0);
        world.setBlock(i + 1, j + 26, k + 0, 0);
        world.setBlock(i + 1, j + 26, k + 1, 0);
        world.setBlock(i + 1, j + 26, k + 2, 0);
        world.setBlock(i + 1, j + 26, k + 3, 0);
        world.setBlock(i + 1, j + 26, k + 4, 0);
        world.setBlock(i + 1, j + 26, k + 5, 0);
        world.setBlock(i + 2, j + 0, k + 0, IceikaBlockHelper.IceGrass.blockID);
        world.setBlock(i + 2, j + 0, k + 1, IceikaBlockHelper.IceGrass.blockID);
        world.setBlock(i + 2, j + 0, k + 2, Block.dirt.blockID);
        world.setBlock(i + 2, j + 0, k + 3, Block.dirt.blockID);
        world.setBlock(i + 2, j + 0, k + 4, IceikaBlockHelper.IceGrass.blockID);
        world.setBlock(i + 2, j + 0, k + 5, IceikaBlockHelper.IceGrass.blockID);
        world.setBlock(i + 2, j + 1, k + 0, 0);
        world.setBlock(i + 2, j + 1, k + 1, 0);
        world.setBlock(i + 2, j + 1, k + 2, IceikaBlockHelper.IceLog.blockID);
        world.setBlock(i + 2, j + 1, k + 3, IceikaBlockHelper.IceLog.blockID);
        world.setBlock(i + 2, j + 1, k + 4, 0);
        world.setBlock(i + 2, j + 1, k + 5, 0);
        world.setBlock(i + 2, j + 2, k + 0, 0);
        world.setBlock(i + 2, j + 2, k + 1, 0);
        world.setBlock(i + 2, j + 2, k + 2, IceikaBlockHelper.IceLog.blockID);
        world.setBlock(i + 2, j + 2, k + 3, IceikaBlockHelper.IceLog.blockID);
        world.setBlock(i + 2, j + 2, k + 4, 0);
        world.setBlock(i + 2, j + 2, k + 5, 0);
        world.setBlock(i + 2, j + 3, k + 0, 0);
        world.setBlock(i + 2, j + 3, k + 1, 0);
        world.setBlock(i + 2, j + 3, k + 2, IceikaBlockHelper.IceLog.blockID);
        world.setBlock(i + 2, j + 3, k + 3, IceikaBlockHelper.IceLog.blockID);
        world.setBlock(i + 2, j + 3, k + 4, 0);
        world.setBlock(i + 2, j + 3, k + 5, 0);
        world.setBlock(i + 2, j + 4, k + 0, IceikaBlockHelper.IceLeaves.blockID);
        world.setBlock(i + 2, j + 4, k + 1, IceikaBlockHelper.IceLeaves.blockID);
        world.setBlock(i + 2, j + 4, k + 2, IceikaBlockHelper.IceLog.blockID);
        world.setBlock(i + 2, j + 4, k + 3, IceikaBlockHelper.IceLog.blockID);
        world.setBlock(i + 2, j + 4, k + 4, IceikaBlockHelper.IceLeaves.blockID);
        world.setBlock(i + 2, j + 4, k + 5, IceikaBlockHelper.IceLeaves.blockID);
        world.setBlock(i + 2, j + 5, k + 0, 0);
        world.setBlock(i + 2, j + 5, k + 1, IceikaBlockHelper.IceLeaves.blockID);
        world.setBlock(i + 2, j + 5, k + 2, IceikaBlockHelper.IceLog.blockID);
        world.setBlock(i + 2, j + 5, k + 3, IceikaBlockHelper.IceLog.blockID);
        world.setBlock(i + 2, j + 5, k + 4, IceikaBlockHelper.IceLeaves.blockID);
        world.setBlock(i + 2, j + 5, k + 5, 0);
        world.setBlock(i + 2, j + 6, k + 0, 0);
        world.setBlock(i + 2, j + 6, k + 1, 0);
        world.setBlock(i + 2, j + 6, k + 2, IceikaBlockHelper.IceLog.blockID);
        world.setBlock(i + 2, j + 6, k + 3, IceikaBlockHelper.IceLog.blockID);
        world.setBlock(i + 2, j + 6, k + 4, 0);
        world.setBlock(i + 2, j + 6, k + 5, 0);
        world.setBlock(i + 2, j + 7, k + 0, IceikaBlockHelper.IceLeaves.blockID);
        world.setBlock(i + 2, j + 7, k + 1, IceikaBlockHelper.IceLeaves.blockID);
        world.setBlock(i + 2, j + 7, k + 2, IceikaBlockHelper.IceLog.blockID);
        world.setBlock(i + 2, j + 7, k + 3, IceikaBlockHelper.IceLog.blockID);
        world.setBlock(i + 2, j + 7, k + 4, IceikaBlockHelper.IceLeaves.blockID);
        world.setBlock(i + 2, j + 7, k + 5, IceikaBlockHelper.IceLeaves.blockID);
        world.setBlock(i + 2, j + 8, k + 0, 0);
        world.setBlock(i + 2, j + 8, k + 1, IceikaBlockHelper.IceLeaves.blockID);
        world.setBlock(i + 2, j + 8, k + 2, IceikaBlockHelper.IceLog.blockID);
        world.setBlock(i + 2, j + 8, k + 3, IceikaBlockHelper.IceLog.blockID);
        world.setBlock(i + 2, j + 8, k + 4, IceikaBlockHelper.IceLeaves.blockID);
        world.setBlock(i + 2, j + 8, k + 5, 0);
        world.setBlock(i + 2, j + 9, k + 0, 0);
        world.setBlock(i + 2, j + 9, k + 1, 0);
        world.setBlock(i + 2, j + 9, k + 2, IceikaBlockHelper.IceLog.blockID);
        world.setBlock(i + 2, j + 9, k + 3, IceikaBlockHelper.IceLog.blockID);
        world.setBlock(i + 2, j + 9, k + 4, 0);
        world.setBlock(i + 2, j + 9, k + 5, 0);
        world.setBlock(i + 2, j + 10, k + 0, IceikaBlockHelper.IceLeaves.blockID);
        world.setBlock(i + 2, j + 10, k + 1, IceikaBlockHelper.IceLeaves.blockID);
        world.setBlock(i + 2, j + 10, k + 2, IceikaBlockHelper.IceLog.blockID);
        world.setBlock(i + 2, j + 10, k + 3, IceikaBlockHelper.IceLog.blockID);
        world.setBlock(i + 2, j + 10, k + 4, IceikaBlockHelper.IceLeaves.blockID);
        world.setBlock(i + 2, j + 10, k + 5, IceikaBlockHelper.IceLeaves.blockID);
        world.setBlock(i + 2, j + 11, k + 0, 0);
        world.setBlock(i + 2, j + 11, k + 1, IceikaBlockHelper.IceLeaves.blockID);
        world.setBlock(i + 2, j + 11, k + 2, IceikaBlockHelper.IceLog.blockID);
        world.setBlock(i + 2, j + 11, k + 3, IceikaBlockHelper.IceLog.blockID);
        world.setBlock(i + 2, j + 11, k + 4, IceikaBlockHelper.IceLeaves.blockID);
        world.setBlock(i + 2, j + 11, k + 5, 0);
        world.setBlock(i + 2, j + 12, k + 0, 0);
        world.setBlock(i + 2, j + 12, k + 1, 0);
        world.setBlock(i + 2, j + 12, k + 2, IceikaBlockHelper.IceLog.blockID);
        world.setBlock(i + 2, j + 12, k + 3, IceikaBlockHelper.IceLog.blockID);
        world.setBlock(i + 2, j + 12, k + 4, 0);
        world.setBlock(i + 2, j + 12, k + 5, 0);
        world.setBlock(i + 2, j + 13, k + 0, IceikaBlockHelper.IceLeaves.blockID);
        world.setBlock(i + 2, j + 13, k + 1, IceikaBlockHelper.IceLeaves.blockID);
        world.setBlock(i + 2, j + 13, k + 2, IceikaBlockHelper.IceLog.blockID);
        world.setBlock(i + 2, j + 13, k + 3, IceikaBlockHelper.IceLog.blockID);
        world.setBlock(i + 2, j + 13, k + 4, IceikaBlockHelper.IceLeaves.blockID);
        world.setBlock(i + 2, j + 13, k + 5, IceikaBlockHelper.IceLeaves.blockID);
        world.setBlock(i + 2, j + 14, k + 0, 0);
        world.setBlock(i + 2, j + 14, k + 1, IceikaBlockHelper.IceLeaves.blockID);
        world.setBlock(i + 2, j + 14, k + 2, IceikaBlockHelper.IceLog.blockID);
        world.setBlock(i + 2, j + 14, k + 3, IceikaBlockHelper.IceLog.blockID);
        world.setBlock(i + 2, j + 14, k + 4, IceikaBlockHelper.IceLeaves.blockID);
        world.setBlock(i + 2, j + 14, k + 5, 0);
        world.setBlock(i + 2, j + 15, k + 0, 0);
        world.setBlock(i + 2, j + 15, k + 1, 0);
        world.setBlock(i + 2, j + 15, k + 2, IceikaBlockHelper.IceLog.blockID);
        world.setBlock(i + 2, j + 15, k + 3, IceikaBlockHelper.IceLog.blockID);
        world.setBlock(i + 2, j + 15, k + 4, 0);
        world.setBlock(i + 2, j + 15, k + 5, 0);
        world.setBlock(i + 2, j + 16, k + 0, IceikaBlockHelper.IceLeaves.blockID);
        world.setBlock(i + 2, j + 16, k + 1, IceikaBlockHelper.IceLeaves.blockID);
        world.setBlock(i + 2, j + 16, k + 2, IceikaBlockHelper.IceLog.blockID);
        world.setBlock(i + 2, j + 16, k + 3, IceikaBlockHelper.IceLog.blockID);
        world.setBlock(i + 2, j + 16, k + 4, IceikaBlockHelper.IceLeaves.blockID);
        world.setBlock(i + 2, j + 16, k + 5, IceikaBlockHelper.IceLeaves.blockID);
        world.setBlock(i + 2, j + 17, k + 0, 0);
        world.setBlock(i + 2, j + 17, k + 1, IceikaBlockHelper.IceLeaves.blockID);
        world.setBlock(i + 2, j + 17, k + 2, IceikaBlockHelper.IceLog.blockID);
        world.setBlock(i + 2, j + 17, k + 3, IceikaBlockHelper.IceLog.blockID);
        world.setBlock(i + 2, j + 17, k + 4, IceikaBlockHelper.IceLeaves.blockID);
        world.setBlock(i + 2, j + 17, k + 5, 0);
        world.setBlock(i + 2, j + 18, k + 0, 0);
        world.setBlock(i + 2, j + 18, k + 1, 0);
        world.setBlock(i + 2, j + 18, k + 2, IceikaBlockHelper.IceLog.blockID);
        world.setBlock(i + 2, j + 18, k + 3, IceikaBlockHelper.IceLog.blockID);
        world.setBlock(i + 2, j + 18, k + 4, 0);
        world.setBlock(i + 2, j + 18, k + 5, 0);
        world.setBlock(i + 2, j + 19, k + 0, IceikaBlockHelper.IceLeaves.blockID);
        world.setBlock(i + 2, j + 19, k + 1, IceikaBlockHelper.IceLeaves.blockID);
        world.setBlock(i + 2, j + 19, k + 2, IceikaBlockHelper.IceLog.blockID);
        world.setBlock(i + 2, j + 19, k + 3, IceikaBlockHelper.IceLog.blockID);
        world.setBlock(i + 2, j + 19, k + 4, IceikaBlockHelper.IceLeaves.blockID);
        world.setBlock(i + 2, j + 19, k + 5, IceikaBlockHelper.IceLeaves.blockID);
        world.setBlock(i + 2, j + 20, k + 0, 0);
        world.setBlock(i + 2, j + 20, k + 1, IceikaBlockHelper.IceLeaves.blockID);
        world.setBlock(i + 2, j + 20, k + 2, IceikaBlockHelper.IceLog.blockID);
        world.setBlock(i + 2, j + 20, k + 3, IceikaBlockHelper.IceLog.blockID);
        world.setBlock(i + 2, j + 20, k + 4, IceikaBlockHelper.IceLeaves.blockID);
        world.setBlock(i + 2, j + 20, k + 5, 0);
        world.setBlock(i + 2, j + 21, k + 0, 0);
        world.setBlock(i + 2, j + 21, k + 1, 0);
        world.setBlock(i + 2, j + 21, k + 2, IceikaBlockHelper.IceLog.blockID);
        world.setBlock(i + 2, j + 21, k + 3, IceikaBlockHelper.IceLog.blockID);
        world.setBlock(i + 2, j + 21, k + 4, 0);
        world.setBlock(i + 2, j + 21, k + 5, 0);
        world.setBlock(i + 2, j + 22, k + 0, IceikaBlockHelper.IceLeaves.blockID);
        world.setBlock(i + 2, j + 22, k + 1, IceikaBlockHelper.IceLeaves.blockID);
        world.setBlock(i + 2, j + 22, k + 2, IceikaBlockHelper.IceLog.blockID);
        world.setBlock(i + 2, j + 22, k + 3, IceikaBlockHelper.IceLog.blockID);
        world.setBlock(i + 2, j + 22, k + 4, IceikaBlockHelper.IceLeaves.blockID);
        world.setBlock(i + 2, j + 22, k + 5, IceikaBlockHelper.IceLeaves.blockID);
        world.setBlock(i + 2, j + 23, k + 0, 0);
        world.setBlock(i + 2, j + 23, k + 1, 0);
        world.setBlock(i + 2, j + 23, k + 2, IceikaBlockHelper.IceLog.blockID);
        world.setBlock(i + 2, j + 23, k + 3, IceikaBlockHelper.IceLog.blockID);
        world.setBlock(i + 2, j + 23, k + 4, 0);
        world.setBlock(i + 2, j + 23, k + 5, 0);
        world.setBlock(i + 2, j + 24, k + 0, IceikaBlockHelper.IceLeaves.blockID);
        world.setBlock(i + 2, j + 24, k + 1, IceikaBlockHelper.IceLeaves.blockID);
        world.setBlock(i + 2, j + 24, k + 2, IceikaBlockHelper.IceLog.blockID);
        world.setBlock(i + 2, j + 24, k + 3, IceikaBlockHelper.IceLog.blockID);
        world.setBlock(i + 2, j + 24, k + 4, IceikaBlockHelper.IceLeaves.blockID);
        world.setBlock(i + 2, j + 24, k + 5, IceikaBlockHelper.IceLeaves.blockID);
        world.setBlock(i + 2, j + 25, k + 0, 0);
        world.setBlock(i + 2, j + 25, k + 1, IceikaBlockHelper.IceLeaves.blockID);
        world.setBlock(i + 2, j + 25, k + 2, IceikaBlockHelper.IceLeaves.blockID);
        world.setBlock(i + 2, j + 25, k + 3, IceikaBlockHelper.IceLeaves.blockID);
        world.setBlock(i + 2, j + 25, k + 4, IceikaBlockHelper.IceLeaves.blockID);
        world.setBlock(i + 2, j + 25, k + 5, 0);
        world.setBlock(i + 2, j + 26, k + 0, 0);
        world.setBlock(i + 2, j + 26, k + 1, 0);
        world.setBlock(i + 2, j + 26, k + 2, IceikaBlockHelper.IceLeaves.blockID);
        world.setBlock(i + 2, j + 26, k + 3, IceikaBlockHelper.IceLeaves.blockID);
        world.setBlock(i + 2, j + 26, k + 4, 0);
        world.setBlock(i + 2, j + 26, k + 5, 0);
        world.setBlock(i + 3, j + 0, k + 0, IceikaBlockHelper.IceGrass.blockID);
        world.setBlock(i + 3, j + 0, k + 1, IceikaBlockHelper.IceGrass.blockID);
        world.setBlock(i + 3, j + 0, k + 2, Block.dirt.blockID);
        world.setBlock(i + 3, j + 0, k + 3, Block.dirt.blockID);
        world.setBlock(i + 3, j + 0, k + 4, IceikaBlockHelper.IceGrass.blockID);
        world.setBlock(i + 3, j + 0, k + 5, IceikaBlockHelper.IceGrass.blockID);
        world.setBlock(i + 3, j + 1, k + 0, 0);
        world.setBlock(i + 3, j + 1, k + 1, 0);
        world.setBlock(i + 3, j + 1, k + 2, IceikaBlockHelper.IceLog.blockID);
        world.setBlock(i + 3, j + 1, k + 3, IceikaBlockHelper.IceLog.blockID);
        world.setBlock(i + 3, j + 1, k + 4, 0);
        world.setBlock(i + 3, j + 1, k + 5, 0);
        world.setBlock(i + 3, j + 2, k + 0, 0);
        world.setBlock(i + 3, j + 2, k + 1, 0);
        world.setBlock(i + 3, j + 2, k + 2, IceikaBlockHelper.IceLog.blockID);
        world.setBlock(i + 3, j + 2, k + 3, IceikaBlockHelper.IceLog.blockID);
        world.setBlock(i + 3, j + 2, k + 4, 0);
        world.setBlock(i + 3, j + 2, k + 5, 0);
        world.setBlock(i + 3, j + 3, k + 0, 0);
        world.setBlock(i + 3, j + 3, k + 1, 0);
        world.setBlock(i + 3, j + 3, k + 2, IceikaBlockHelper.IceLog.blockID);
        world.setBlock(i + 3, j + 3, k + 3, IceikaBlockHelper.IceLog.blockID);
        world.setBlock(i + 3, j + 3, k + 4, 0);
        world.setBlock(i + 3, j + 3, k + 5, 0);
        world.setBlock(i + 3, j + 4, k + 0, IceikaBlockHelper.IceLeaves.blockID);
        world.setBlock(i + 3, j + 4, k + 1, IceikaBlockHelper.IceLeaves.blockID);
        world.setBlock(i + 3, j + 4, k + 2, IceikaBlockHelper.IceLog.blockID);
        world.setBlock(i + 3, j + 4, k + 3, IceikaBlockHelper.IceLog.blockID);
        world.setBlock(i + 3, j + 4, k + 4, IceikaBlockHelper.IceLeaves.blockID);
        world.setBlock(i + 3, j + 4, k + 5, IceikaBlockHelper.IceLeaves.blockID);
        world.setBlock(i + 3, j + 5, k + 0, 0);
        world.setBlock(i + 3, j + 5, k + 1, IceikaBlockHelper.IceLeaves.blockID);
        world.setBlock(i + 3, j + 5, k + 2, IceikaBlockHelper.IceLog.blockID);
        world.setBlock(i + 3, j + 5, k + 3, IceikaBlockHelper.IceLog.blockID);
        world.setBlock(i + 3, j + 5, k + 4, IceikaBlockHelper.IceLeaves.blockID);
        world.setBlock(i + 3, j + 5, k + 5, 0);
        world.setBlock(i + 3, j + 6, k + 0, 0);
        world.setBlock(i + 3, j + 6, k + 1, 0);
        world.setBlock(i + 3, j + 6, k + 2, IceikaBlockHelper.IceLog.blockID);
        world.setBlock(i + 3, j + 6, k + 3, IceikaBlockHelper.IceLog.blockID);
        world.setBlock(i + 3, j + 6, k + 4, 0);
        world.setBlock(i + 3, j + 6, k + 5, 0);
        world.setBlock(i + 3, j + 7, k + 0, IceikaBlockHelper.IceLeaves.blockID);
        world.setBlock(i + 3, j + 7, k + 1, IceikaBlockHelper.IceLeaves.blockID);
        world.setBlock(i + 3, j + 7, k + 2, IceikaBlockHelper.IceLog.blockID);
        world.setBlock(i + 3, j + 7, k + 3, IceikaBlockHelper.IceLog.blockID);
        world.setBlock(i + 3, j + 7, k + 4, IceikaBlockHelper.IceLeaves.blockID);
        world.setBlock(i + 3, j + 7, k + 5, IceikaBlockHelper.IceLeaves.blockID);
        world.setBlock(i + 3, j + 8, k + 0, 0);
        world.setBlock(i + 3, j + 8, k + 1, IceikaBlockHelper.IceLeaves.blockID);
        world.setBlock(i + 3, j + 8, k + 2, IceikaBlockHelper.IceLog.blockID);
        world.setBlock(i + 3, j + 8, k + 3, IceikaBlockHelper.IceLog.blockID);
        world.setBlock(i + 3, j + 8, k + 4, IceikaBlockHelper.IceLeaves.blockID);
        world.setBlock(i + 3, j + 8, k + 5, 0);
        world.setBlock(i + 3, j + 9, k + 0, 0);
        world.setBlock(i + 3, j + 9, k + 1, 0);
        world.setBlock(i + 3, j + 9, k + 2, IceikaBlockHelper.IceLog.blockID);
        world.setBlock(i + 3, j + 9, k + 3, IceikaBlockHelper.IceLog.blockID);
        world.setBlock(i + 3, j + 9, k + 4, 0);
        world.setBlock(i + 3, j + 9, k + 5, 0);
        world.setBlock(i + 3, j + 10, k + 0, IceikaBlockHelper.IceLeaves.blockID);
        world.setBlock(i + 3, j + 10, k + 1, IceikaBlockHelper.IceLeaves.blockID);
        world.setBlock(i + 3, j + 10, k + 2, IceikaBlockHelper.IceLog.blockID);
        world.setBlock(i + 3, j + 10, k + 3, IceikaBlockHelper.IceLog.blockID);
        world.setBlock(i + 3, j + 10, k + 4, IceikaBlockHelper.IceLeaves.blockID);
        world.setBlock(i + 3, j + 10, k + 5, IceikaBlockHelper.IceLeaves.blockID);
        world.setBlock(i + 3, j + 11, k + 0, 0);
        world.setBlock(i + 3, j + 11, k + 1, IceikaBlockHelper.IceLeaves.blockID);
        world.setBlock(i + 3, j + 11, k + 2, IceikaBlockHelper.IceLog.blockID);
        world.setBlock(i + 3, j + 11, k + 3, IceikaBlockHelper.IceLog.blockID);
        world.setBlock(i + 3, j + 11, k + 4, IceikaBlockHelper.IceLeaves.blockID);
        world.setBlock(i + 3, j + 11, k + 5, 0);
        world.setBlock(i + 3, j + 12, k + 0, 0);
        world.setBlock(i + 3, j + 12, k + 1, 0);
        world.setBlock(i + 3, j + 12, k + 2, IceikaBlockHelper.IceLog.blockID);
        world.setBlock(i + 3, j + 12, k + 3, IceikaBlockHelper.IceLog.blockID);
        world.setBlock(i + 3, j + 12, k + 4, 0);
        world.setBlock(i + 3, j + 12, k + 5, 0);
        world.setBlock(i + 3, j + 13, k + 0, IceikaBlockHelper.IceLeaves.blockID);
        world.setBlock(i + 3, j + 13, k + 1, IceikaBlockHelper.IceLeaves.blockID);
        world.setBlock(i + 3, j + 13, k + 2, IceikaBlockHelper.IceLog.blockID);
        world.setBlock(i + 3, j + 13, k + 3, IceikaBlockHelper.IceLog.blockID);
        world.setBlock(i + 3, j + 13, k + 4, IceikaBlockHelper.IceLeaves.blockID);
        world.setBlock(i + 3, j + 13, k + 5, IceikaBlockHelper.IceLeaves.blockID);
        world.setBlock(i + 3, j + 14, k + 0, 0);
        world.setBlock(i + 3, j + 14, k + 1, IceikaBlockHelper.IceLeaves.blockID);
        world.setBlock(i + 3, j + 14, k + 2, IceikaBlockHelper.IceLog.blockID);
        world.setBlock(i + 3, j + 14, k + 3, IceikaBlockHelper.IceLog.blockID);
        world.setBlock(i + 3, j + 14, k + 4, IceikaBlockHelper.IceLeaves.blockID);
        world.setBlock(i + 3, j + 14, k + 5, 0);
        world.setBlock(i + 3, j + 15, k + 0, 0);
        world.setBlock(i + 3, j + 15, k + 1, 0);
        world.setBlock(i + 3, j + 15, k + 2, IceikaBlockHelper.IceLog.blockID);
        world.setBlock(i + 3, j + 15, k + 3, IceikaBlockHelper.IceLog.blockID);
        world.setBlock(i + 3, j + 15, k + 4, 0);
        world.setBlock(i + 3, j + 15, k + 5, 0);
        world.setBlock(i + 3, j + 16, k + 0, IceikaBlockHelper.IceLeaves.blockID);
        world.setBlock(i + 3, j + 16, k + 1, IceikaBlockHelper.IceLeaves.blockID);
        world.setBlock(i + 3, j + 16, k + 2, IceikaBlockHelper.IceLog.blockID);
        world.setBlock(i + 3, j + 16, k + 3, IceikaBlockHelper.IceLog.blockID);
        world.setBlock(i + 3, j + 16, k + 4, IceikaBlockHelper.IceLeaves.blockID);
        world.setBlock(i + 3, j + 16, k + 5, IceikaBlockHelper.IceLeaves.blockID);
        world.setBlock(i + 3, j + 17, k + 0, 0);
        world.setBlock(i + 3, j + 17, k + 1, IceikaBlockHelper.IceLeaves.blockID);
        world.setBlock(i + 3, j + 17, k + 2, IceikaBlockHelper.IceLog.blockID);
        world.setBlock(i + 3, j + 17, k + 3, IceikaBlockHelper.IceLog.blockID);
        world.setBlock(i + 3, j + 17, k + 4, IceikaBlockHelper.IceLeaves.blockID);
        world.setBlock(i + 3, j + 17, k + 5, 0);
        world.setBlock(i + 3, j + 18, k + 0, 0);
        world.setBlock(i + 3, j + 18, k + 1, 0);
        world.setBlock(i + 3, j + 18, k + 2, IceikaBlockHelper.IceLog.blockID);
        world.setBlock(i + 3, j + 18, k + 3, IceikaBlockHelper.IceLog.blockID);
        world.setBlock(i + 3, j + 18, k + 4, 0);
        world.setBlock(i + 3, j + 18, k + 5, 0);
        world.setBlock(i + 3, j + 19, k + 0, IceikaBlockHelper.IceLeaves.blockID);
        world.setBlock(i + 3, j + 19, k + 1, IceikaBlockHelper.IceLeaves.blockID);
        world.setBlock(i + 3, j + 19, k + 2, IceikaBlockHelper.IceLog.blockID);
        world.setBlock(i + 3, j + 19, k + 3, IceikaBlockHelper.IceLog.blockID);
        world.setBlock(i + 3, j + 19, k + 4, IceikaBlockHelper.IceLeaves.blockID);
        world.setBlock(i + 3, j + 19, k + 5, IceikaBlockHelper.IceLeaves.blockID);
        world.setBlock(i + 3, j + 20, k + 0, 0);
        world.setBlock(i + 3, j + 20, k + 1, IceikaBlockHelper.IceLeaves.blockID);
        world.setBlock(i + 3, j + 20, k + 2, IceikaBlockHelper.IceLog.blockID);
        world.setBlock(i + 3, j + 20, k + 3, IceikaBlockHelper.IceLog.blockID);
        world.setBlock(i + 3, j + 20, k + 4, IceikaBlockHelper.IceLeaves.blockID);
        world.setBlock(i + 3, j + 20, k + 5, 0);
        world.setBlock(i + 3, j + 21, k + 0, 0);
        world.setBlock(i + 3, j + 21, k + 1, 0);
        world.setBlock(i + 3, j + 21, k + 2, IceikaBlockHelper.IceLog.blockID);
        world.setBlock(i + 3, j + 21, k + 3, IceikaBlockHelper.IceLog.blockID);
        world.setBlock(i + 3, j + 21, k + 4, 0);
        world.setBlock(i + 3, j + 21, k + 5, 0);
        world.setBlock(i + 3, j + 22, k + 0, IceikaBlockHelper.IceLeaves.blockID);
        world.setBlock(i + 3, j + 22, k + 1, IceikaBlockHelper.IceLeaves.blockID);
        world.setBlock(i + 3, j + 22, k + 2, IceikaBlockHelper.IceLog.blockID);
        world.setBlock(i + 3, j + 22, k + 3, IceikaBlockHelper.IceLog.blockID);
        world.setBlock(i + 3, j + 22, k + 4, IceikaBlockHelper.IceLeaves.blockID);
        world.setBlock(i + 3, j + 22, k + 5, IceikaBlockHelper.IceLeaves.blockID);
        world.setBlock(i + 3, j + 23, k + 0, 0);
        world.setBlock(i + 3, j + 23, k + 1, 0);
        world.setBlock(i + 3, j + 23, k + 2, IceikaBlockHelper.IceLog.blockID);
        world.setBlock(i + 3, j + 23, k + 3, IceikaBlockHelper.IceLog.blockID);
        world.setBlock(i + 3, j + 23, k + 4, 0);
        world.setBlock(i + 3, j + 23, k + 5, 0);
        world.setBlock(i + 3, j + 24, k + 0, IceikaBlockHelper.IceLeaves.blockID);
        world.setBlock(i + 3, j + 24, k + 1, IceikaBlockHelper.IceLeaves.blockID);
        world.setBlock(i + 3, j + 24, k + 2, IceikaBlockHelper.IceLog.blockID);
        world.setBlock(i + 3, j + 24, k + 3, IceikaBlockHelper.IceLog.blockID);
        world.setBlock(i + 3, j + 24, k + 4, IceikaBlockHelper.IceLeaves.blockID);
        world.setBlock(i + 3, j + 24, k + 5, IceikaBlockHelper.IceLeaves.blockID);
        world.setBlock(i + 3, j + 25, k + 0, 0);
        world.setBlock(i + 3, j + 25, k + 1, IceikaBlockHelper.IceLeaves.blockID);
        world.setBlock(i + 3, j + 25, k + 2, IceikaBlockHelper.IceLeaves.blockID);
        world.setBlock(i + 3, j + 25, k + 3, IceikaBlockHelper.IceLeaves.blockID);
        world.setBlock(i + 3, j + 25, k + 4, IceikaBlockHelper.IceLeaves.blockID);
        world.setBlock(i + 3, j + 25, k + 5, 0);
        world.setBlock(i + 3, j + 26, k + 0, 0);
        world.setBlock(i + 3, j + 26, k + 1, 0);
        world.setBlock(i + 3, j + 26, k + 2, IceikaBlockHelper.IceLeaves.blockID);
        world.setBlock(i + 3, j + 26, k + 3, IceikaBlockHelper.IceLeaves.blockID);
        world.setBlock(i + 3, j + 26, k + 4, 0);
        world.setBlock(i + 3, j + 26, k + 5, 0);
        world.setBlock(i + 4, j + 0, k + 0, IceikaBlockHelper.IceGrass.blockID);
        world.setBlock(i + 4, j + 0, k + 1, IceikaBlockHelper.IceGrass.blockID);
        world.setBlock(i + 4, j + 0, k + 2, IceikaBlockHelper.IceGrass.blockID);
        world.setBlock(i + 4, j + 0, k + 3, IceikaBlockHelper.IceGrass.blockID);
        world.setBlock(i + 4, j + 0, k + 4, IceikaBlockHelper.IceGrass.blockID);
        world.setBlock(i + 4, j + 0, k + 5, IceikaBlockHelper.IceGrass.blockID);
        world.setBlock(i + 4, j + 1, k + 0, 0);
        world.setBlock(i + 4, j + 1, k + 1, 0);
        world.setBlock(i + 4, j + 1, k + 2, 0);
        world.setBlock(i + 4, j + 1, k + 3, 0);
        world.setBlock(i + 4, j + 1, k + 4, 0);
        world.setBlock(i + 4, j + 1, k + 5, 0);
        world.setBlock(i + 4, j + 2, k + 0, 0);
        world.setBlock(i + 4, j + 2, k + 1, 0);
        world.setBlock(i + 4, j + 2, k + 2, 0);
        world.setBlock(i + 4, j + 2, k + 3, 0);
        world.setBlock(i + 4, j + 2, k + 4, 0);
        world.setBlock(i + 4, j + 2, k + 5, 0);
        world.setBlock(i + 4, j + 3, k + 0, 0);
        world.setBlock(i + 4, j + 3, k + 1, 0);
        world.setBlock(i + 4, j + 3, k + 2, 0);
        world.setBlock(i + 4, j + 3, k + 3, 0);
        world.setBlock(i + 4, j + 3, k + 4, 0);
        world.setBlock(i + 4, j + 3, k + 5, 0);
        world.setBlock(i + 4, j + 4, k + 0, IceikaBlockHelper.IceLeaves.blockID);
        world.setBlock(i + 4, j + 4, k + 1, IceikaBlockHelper.IceLeaves.blockID);
        world.setBlock(i + 4, j + 4, k + 2, IceikaBlockHelper.IceLeaves.blockID);
        world.setBlock(i + 4, j + 4, k + 3, IceikaBlockHelper.IceLeaves.blockID);
        world.setBlock(i + 4, j + 4, k + 4, IceikaBlockHelper.IceLeaves.blockID);
        world.setBlock(i + 4, j + 4, k + 5, IceikaBlockHelper.IceLeaves.blockID);
        world.setBlock(i + 4, j + 5, k + 0, 0);
        world.setBlock(i + 4, j + 5, k + 1, IceikaBlockHelper.IceLeaves.blockID);
        world.setBlock(i + 4, j + 5, k + 2, IceikaBlockHelper.IceLeaves.blockID);
        world.setBlock(i + 4, j + 5, k + 3, IceikaBlockHelper.IceLeaves.blockID);
        world.setBlock(i + 4, j + 5, k + 4, IceikaBlockHelper.IceLeaves.blockID);
        world.setBlock(i + 4, j + 5, k + 5, 0);
        world.setBlock(i + 4, j + 6, k + 0, 0);
        world.setBlock(i + 4, j + 6, k + 1, 0);
        world.setBlock(i + 4, j + 6, k + 2, 0);
        world.setBlock(i + 4, j + 6, k + 3, 0);
        world.setBlock(i + 4, j + 6, k + 4, 0);
        world.setBlock(i + 4, j + 6, k + 5, 0);
        world.setBlock(i + 4, j + 7, k + 0, IceikaBlockHelper.IceLeaves.blockID);
        world.setBlock(i + 4, j + 7, k + 1, IceikaBlockHelper.IceLeaves.blockID);
        world.setBlock(i + 4, j + 7, k + 2, IceikaBlockHelper.IceLeaves.blockID);
        world.setBlock(i + 4, j + 7, k + 3, IceikaBlockHelper.IceLeaves.blockID);
        world.setBlock(i + 4, j + 7, k + 4, IceikaBlockHelper.IceLeaves.blockID);
        world.setBlock(i + 4, j + 7, k + 5, IceikaBlockHelper.IceLeaves.blockID);
        world.setBlock(i + 4, j + 8, k + 0, 0);
        world.setBlock(i + 4, j + 8, k + 1, IceikaBlockHelper.IceLeaves.blockID);
        world.setBlock(i + 4, j + 8, k + 2, IceikaBlockHelper.IceLeaves.blockID);
        world.setBlock(i + 4, j + 8, k + 3, IceikaBlockHelper.IceLeaves.blockID);
        world.setBlock(i + 4, j + 8, k + 4, IceikaBlockHelper.IceLeaves.blockID);
        world.setBlock(i + 4, j + 8, k + 5, 0);
        world.setBlock(i + 4, j + 9, k + 0, 0);
        world.setBlock(i + 4, j + 9, k + 1, 0);
        world.setBlock(i + 4, j + 9, k + 2, 0);
        world.setBlock(i + 4, j + 9, k + 3, 0);
        world.setBlock(i + 4, j + 9, k + 4, 0);
        world.setBlock(i + 4, j + 9, k + 5, 0);
        world.setBlock(i + 4, j + 10, k + 0, IceikaBlockHelper.IceLeaves.blockID);
        world.setBlock(i + 4, j + 10, k + 1, IceikaBlockHelper.IceLeaves.blockID);
        world.setBlock(i + 4, j + 10, k + 2, IceikaBlockHelper.IceLeaves.blockID);
        world.setBlock(i + 4, j + 10, k + 3, IceikaBlockHelper.IceLeaves.blockID);
        world.setBlock(i + 4, j + 10, k + 4, IceikaBlockHelper.IceLeaves.blockID);
        world.setBlock(i + 4, j + 10, k + 5, IceikaBlockHelper.IceLeaves.blockID);
        world.setBlock(i + 4, j + 11, k + 0, 0);
        world.setBlock(i + 4, j + 11, k + 1, IceikaBlockHelper.IceLeaves.blockID);
        world.setBlock(i + 4, j + 11, k + 2, IceikaBlockHelper.IceLeaves.blockID);
        world.setBlock(i + 4, j + 11, k + 3, IceikaBlockHelper.IceLeaves.blockID);
        world.setBlock(i + 4, j + 11, k + 4, IceikaBlockHelper.IceLeaves.blockID);
        world.setBlock(i + 4, j + 11, k + 5, 0);
        world.setBlock(i + 4, j + 12, k + 0, 0);
        world.setBlock(i + 4, j + 12, k + 1, 0);
        world.setBlock(i + 4, j + 12, k + 2, 0);
        world.setBlock(i + 4, j + 12, k + 3, 0);
        world.setBlock(i + 4, j + 12, k + 4, 0);
        world.setBlock(i + 4, j + 12, k + 5, 0);
        world.setBlock(i + 4, j + 13, k + 0, IceikaBlockHelper.IceLeaves.blockID);
        world.setBlock(i + 4, j + 13, k + 1, IceikaBlockHelper.IceLeaves.blockID);
        world.setBlock(i + 4, j + 13, k + 2, IceikaBlockHelper.IceLeaves.blockID);
        world.setBlock(i + 4, j + 13, k + 3, IceikaBlockHelper.IceLeaves.blockID);
        world.setBlock(i + 4, j + 13, k + 4, IceikaBlockHelper.IceLeaves.blockID);
        world.setBlock(i + 4, j + 13, k + 5, IceikaBlockHelper.IceLeaves.blockID);
        world.setBlock(i + 4, j + 14, k + 0, 0);
        world.setBlock(i + 4, j + 14, k + 1, IceikaBlockHelper.IceLeaves.blockID);
        world.setBlock(i + 4, j + 14, k + 2, IceikaBlockHelper.IceLeaves.blockID);
        world.setBlock(i + 4, j + 14, k + 3, IceikaBlockHelper.IceLeaves.blockID);
        world.setBlock(i + 4, j + 14, k + 4, IceikaBlockHelper.IceLeaves.blockID);
        world.setBlock(i + 4, j + 14, k + 5, 0);
        world.setBlock(i + 4, j + 15, k + 0, 0);
        world.setBlock(i + 4, j + 15, k + 1, 0);
        world.setBlock(i + 4, j + 15, k + 2, 0);
        world.setBlock(i + 4, j + 15, k + 3, 0);
        world.setBlock(i + 4, j + 15, k + 4, 0);
        world.setBlock(i + 4, j + 15, k + 5, 0);
        world.setBlock(i + 4, j + 16, k + 0, IceikaBlockHelper.IceLeaves.blockID);
        world.setBlock(i + 4, j + 16, k + 1, IceikaBlockHelper.IceLeaves.blockID);
        world.setBlock(i + 4, j + 16, k + 2, IceikaBlockHelper.IceLeaves.blockID);
        world.setBlock(i + 4, j + 16, k + 3, IceikaBlockHelper.IceLeaves.blockID);
        world.setBlock(i + 4, j + 16, k + 4, IceikaBlockHelper.IceLeaves.blockID);
        world.setBlock(i + 4, j + 16, k + 5, IceikaBlockHelper.IceLeaves.blockID);
        world.setBlock(i + 4, j + 17, k + 0, 0);
        world.setBlock(i + 4, j + 17, k + 1, IceikaBlockHelper.IceLeaves.blockID);
        world.setBlock(i + 4, j + 17, k + 2, IceikaBlockHelper.IceLeaves.blockID);
        world.setBlock(i + 4, j + 17, k + 3, IceikaBlockHelper.IceLeaves.blockID);
        world.setBlock(i + 4, j + 17, k + 4, IceikaBlockHelper.IceLeaves.blockID);
        world.setBlock(i + 4, j + 17, k + 5, 0);
        world.setBlock(i + 4, j + 18, k + 0, 0);
        world.setBlock(i + 4, j + 18, k + 1, 0);
        world.setBlock(i + 4, j + 18, k + 2, 0);
        world.setBlock(i + 4, j + 18, k + 3, 0);
        world.setBlock(i + 4, j + 18, k + 4, 0);
        world.setBlock(i + 4, j + 18, k + 5, 0);
        world.setBlock(i + 4, j + 19, k + 0, IceikaBlockHelper.IceLeaves.blockID);
        world.setBlock(i + 4, j + 19, k + 1, IceikaBlockHelper.IceLeaves.blockID);
        world.setBlock(i + 4, j + 19, k + 2, IceikaBlockHelper.IceLeaves.blockID);
        world.setBlock(i + 4, j + 19, k + 3, IceikaBlockHelper.IceLeaves.blockID);
        world.setBlock(i + 4, j + 19, k + 4, IceikaBlockHelper.IceLeaves.blockID);
        world.setBlock(i + 4, j + 19, k + 5, IceikaBlockHelper.IceLeaves.blockID);
        world.setBlock(i + 4, j + 20, k + 0, 0);
        world.setBlock(i + 4, j + 20, k + 1, IceikaBlockHelper.IceLeaves.blockID);
        world.setBlock(i + 4, j + 20, k + 2, IceikaBlockHelper.IceLeaves.blockID);
        world.setBlock(i + 4, j + 20, k + 3, IceikaBlockHelper.IceLeaves.blockID);
        world.setBlock(i + 4, j + 20, k + 4, IceikaBlockHelper.IceLeaves.blockID);
        world.setBlock(i + 4, j + 20, k + 5, 0);
        world.setBlock(i + 4, j + 21, k + 0, 0);
        world.setBlock(i + 4, j + 21, k + 1, 0);
        world.setBlock(i + 4, j + 21, k + 2, 0);
        world.setBlock(i + 4, j + 21, k + 3, 0);
        world.setBlock(i + 4, j + 21, k + 4, 0);
        world.setBlock(i + 4, j + 21, k + 5, 0);
        world.setBlock(i + 4, j + 22, k + 0, IceikaBlockHelper.IceLeaves.blockID);
        world.setBlock(i + 4, j + 22, k + 1, IceikaBlockHelper.IceLeaves.blockID);
        world.setBlock(i + 4, j + 22, k + 2, IceikaBlockHelper.IceLeaves.blockID);
        world.setBlock(i + 4, j + 22, k + 3, IceikaBlockHelper.IceLeaves.blockID);
        world.setBlock(i + 4, j + 22, k + 4, IceikaBlockHelper.IceLeaves.blockID);
        world.setBlock(i + 4, j + 22, k + 5, IceikaBlockHelper.IceLeaves.blockID);
        world.setBlock(i + 4, j + 23, k + 0, 0);
        world.setBlock(i + 4, j + 23, k + 1, 0);
        world.setBlock(i + 4, j + 23, k + 2, 0);
        world.setBlock(i + 4, j + 23, k + 3, 0);
        world.setBlock(i + 4, j + 23, k + 4, 0);
        world.setBlock(i + 4, j + 23, k + 5, 0);
        world.setBlock(i + 4, j + 24, k + 0, IceikaBlockHelper.IceLeaves.blockID);
        world.setBlock(i + 4, j + 24, k + 1, IceikaBlockHelper.IceLeaves.blockID);
        world.setBlock(i + 4, j + 24, k + 2, IceikaBlockHelper.IceLeaves.blockID);
        world.setBlock(i + 4, j + 24, k + 3, IceikaBlockHelper.IceLeaves.blockID);
        world.setBlock(i + 4, j + 24, k + 4, IceikaBlockHelper.IceLeaves.blockID);
        world.setBlock(i + 4, j + 24, k + 5, IceikaBlockHelper.IceLeaves.blockID);
        world.setBlock(i + 4, j + 25, k + 0, 0);
        world.setBlock(i + 4, j + 25, k + 1, IceikaBlockHelper.IceLeaves.blockID);
        world.setBlock(i + 4, j + 25, k + 2, IceikaBlockHelper.IceLeaves.blockID);
        world.setBlock(i + 4, j + 25, k + 3, IceikaBlockHelper.IceLeaves.blockID);
        world.setBlock(i + 4, j + 25, k + 4, IceikaBlockHelper.IceLeaves.blockID);
        world.setBlock(i + 4, j + 25, k + 5, 0);
        world.setBlock(i + 4, j + 26, k + 0, 0);
        world.setBlock(i + 4, j + 26, k + 1, 0);
        world.setBlock(i + 4, j + 26, k + 2, 0);
        world.setBlock(i + 4, j + 26, k + 3, 0);
        world.setBlock(i + 4, j + 26, k + 4, 0);
        world.setBlock(i + 4, j + 26, k + 5, 0);
        world.setBlock(i + 5, j + 0, k + 0, IceikaBlockHelper.IceGrass.blockID);
        world.setBlock(i + 5, j + 0, k + 1, IceikaBlockHelper.IceGrass.blockID);
        world.setBlock(i + 5, j + 0, k + 2, IceikaBlockHelper.IceGrass.blockID);
        world.setBlock(i + 5, j + 0, k + 3, IceikaBlockHelper.IceGrass.blockID);
        world.setBlock(i + 5, j + 0, k + 4, IceikaBlockHelper.IceGrass.blockID);
        world.setBlock(i + 5, j + 0, k + 5, IceikaBlockHelper.IceGrass.blockID);
        world.setBlock(i + 5, j + 1, k + 0, 0);
        world.setBlock(i + 5, j + 1, k + 1, 0);
        world.setBlock(i + 5, j + 1, k + 2, 0);
        world.setBlock(i + 5, j + 1, k + 3, 0);
        world.setBlock(i + 5, j + 1, k + 4, 0);
        world.setBlock(i + 5, j + 1, k + 5, 0);
        world.setBlock(i + 5, j + 2, k + 0, 0);
        world.setBlock(i + 5, j + 2, k + 1, 0);
        world.setBlock(i + 5, j + 2, k + 2, 0);
        world.setBlock(i + 5, j + 2, k + 3, 0);
        world.setBlock(i + 5, j + 2, k + 4, 0);
        world.setBlock(i + 5, j + 2, k + 5, 0);
        world.setBlock(i + 5, j + 3, k + 0, 0);
        world.setBlock(i + 5, j + 3, k + 1, 0);
        world.setBlock(i + 5, j + 3, k + 2, 0);
        world.setBlock(i + 5, j + 3, k + 3, 0);
        world.setBlock(i + 5, j + 3, k + 4, 0);
        world.setBlock(i + 5, j + 3, k + 5, 0);
        world.setBlock(i + 5, j + 4, k + 0, IceikaBlockHelper.IceLeaves.blockID);
        world.setBlock(i + 5, j + 4, k + 1, IceikaBlockHelper.IceLeaves.blockID);
        world.setBlock(i + 5, j + 4, k + 2, IceikaBlockHelper.IceLeaves.blockID);
        world.setBlock(i + 5, j + 4, k + 3, IceikaBlockHelper.IceLeaves.blockID);
        world.setBlock(i + 5, j + 4, k + 4, IceikaBlockHelper.IceLeaves.blockID);
        world.setBlock(i + 5, j + 4, k + 5, IceikaBlockHelper.IceLeaves.blockID);
        world.setBlock(i + 5, j + 5, k + 0, 0);
        world.setBlock(i + 5, j + 5, k + 1, 0);
        world.setBlock(i + 5, j + 5, k + 2, 0);
        world.setBlock(i + 5, j + 5, k + 3, 0);
        world.setBlock(i + 5, j + 5, k + 4, 0);
        world.setBlock(i + 5, j + 5, k + 5, 0);
        world.setBlock(i + 5, j + 6, k + 0, 0);
        world.setBlock(i + 5, j + 6, k + 1, 0);
        world.setBlock(i + 5, j + 6, k + 2, 0);
        world.setBlock(i + 5, j + 6, k + 3, 0);
        world.setBlock(i + 5, j + 6, k + 4, 0);
        world.setBlock(i + 5, j + 6, k + 5, 0);
        world.setBlock(i + 5, j + 7, k + 0, IceikaBlockHelper.IceLeaves.blockID);
        world.setBlock(i + 5, j + 7, k + 1, IceikaBlockHelper.IceLeaves.blockID);
        world.setBlock(i + 5, j + 7, k + 2, IceikaBlockHelper.IceLeaves.blockID);
        world.setBlock(i + 5, j + 7, k + 3, IceikaBlockHelper.IceLeaves.blockID);
        world.setBlock(i + 5, j + 7, k + 4, IceikaBlockHelper.IceLeaves.blockID);
        world.setBlock(i + 5, j + 7, k + 5, IceikaBlockHelper.IceLeaves.blockID);
        world.setBlock(i + 5, j + 8, k + 0, 0);
        world.setBlock(i + 5, j + 8, k + 1, 0);
        world.setBlock(i + 5, j + 8, k + 2, 0);
        world.setBlock(i + 5, j + 8, k + 3, 0);
        world.setBlock(i + 5, j + 8, k + 4, 0);
        world.setBlock(i + 5, j + 8, k + 5, 0);
        world.setBlock(i + 5, j + 9, k + 0, 0);
        world.setBlock(i + 5, j + 9, k + 1, 0);
        world.setBlock(i + 5, j + 9, k + 2, 0);
        world.setBlock(i + 5, j + 9, k + 3, 0);
        world.setBlock(i + 5, j + 9, k + 4, 0);
        world.setBlock(i + 5, j + 9, k + 5, 0);
        world.setBlock(i + 5, j + 10, k + 0, IceikaBlockHelper.IceLeaves.blockID);
        world.setBlock(i + 5, j + 10, k + 1, IceikaBlockHelper.IceLeaves.blockID);
        world.setBlock(i + 5, j + 10, k + 2, IceikaBlockHelper.IceLeaves.blockID);
        world.setBlock(i + 5, j + 10, k + 3, IceikaBlockHelper.IceLeaves.blockID);
        world.setBlock(i + 5, j + 10, k + 4, IceikaBlockHelper.IceLeaves.blockID);
        world.setBlock(i + 5, j + 10, k + 5, IceikaBlockHelper.IceLeaves.blockID);
        world.setBlock(i + 5, j + 11, k + 0, 0);
        world.setBlock(i + 5, j + 11, k + 1, 0);
        world.setBlock(i + 5, j + 11, k + 2, 0);
        world.setBlock(i + 5, j + 11, k + 3, 0);
        world.setBlock(i + 5, j + 11, k + 4, 0);
        world.setBlock(i + 5, j + 11, k + 5, 0);
        world.setBlock(i + 5, j + 12, k + 0, 0);
        world.setBlock(i + 5, j + 12, k + 1, 0);
        world.setBlock(i + 5, j + 12, k + 2, 0);
        world.setBlock(i + 5, j + 12, k + 3, 0);
        world.setBlock(i + 5, j + 12, k + 4, 0);
        world.setBlock(i + 5, j + 12, k + 5, 0);
        world.setBlock(i + 5, j + 13, k + 0, IceikaBlockHelper.IceLeaves.blockID);
        world.setBlock(i + 5, j + 13, k + 1, IceikaBlockHelper.IceLeaves.blockID);
        world.setBlock(i + 5, j + 13, k + 2, IceikaBlockHelper.IceLeaves.blockID);
        world.setBlock(i + 5, j + 13, k + 3, IceikaBlockHelper.IceLeaves.blockID);
        world.setBlock(i + 5, j + 13, k + 4, IceikaBlockHelper.IceLeaves.blockID);
        world.setBlock(i + 5, j + 13, k + 5, IceikaBlockHelper.IceLeaves.blockID);
        world.setBlock(i + 5, j + 14, k + 0, 0);
        world.setBlock(i + 5, j + 14, k + 1, 0);
        world.setBlock(i + 5, j + 14, k + 2, 0);
        world.setBlock(i + 5, j + 14, k + 3, 0);
        world.setBlock(i + 5, j + 14, k + 4, 0);
        world.setBlock(i + 5, j + 14, k + 5, 0);
        world.setBlock(i + 5, j + 15, k + 0, 0);
        world.setBlock(i + 5, j + 15, k + 1, 0);
        world.setBlock(i + 5, j + 15, k + 2, 0);
        world.setBlock(i + 5, j + 15, k + 3, 0);
        world.setBlock(i + 5, j + 15, k + 4, 0);
        world.setBlock(i + 5, j + 15, k + 5, 0);
        world.setBlock(i + 5, j + 16, k + 0, IceikaBlockHelper.IceLeaves.blockID);
        world.setBlock(i + 5, j + 16, k + 1, IceikaBlockHelper.IceLeaves.blockID);
        world.setBlock(i + 5, j + 16, k + 2, IceikaBlockHelper.IceLeaves.blockID);
        world.setBlock(i + 5, j + 16, k + 3, IceikaBlockHelper.IceLeaves.blockID);
        world.setBlock(i + 5, j + 16, k + 4, IceikaBlockHelper.IceLeaves.blockID);
        world.setBlock(i + 5, j + 16, k + 5, IceikaBlockHelper.IceLeaves.blockID);
        world.setBlock(i + 5, j + 17, k + 0, 0);
        world.setBlock(i + 5, j + 17, k + 1, 0);
        world.setBlock(i + 5, j + 17, k + 2, 0);
        world.setBlock(i + 5, j + 17, k + 3, 0);
        world.setBlock(i + 5, j + 17, k + 4, 0);
        world.setBlock(i + 5, j + 17, k + 5, 0);
        world.setBlock(i + 5, j + 18, k + 0, 0);
        world.setBlock(i + 5, j + 18, k + 1, 0);
        world.setBlock(i + 5, j + 18, k + 2, 0);
        world.setBlock(i + 5, j + 18, k + 3, 0);
        world.setBlock(i + 5, j + 18, k + 4, 0);
        world.setBlock(i + 5, j + 18, k + 5, 0);
        world.setBlock(i + 5, j + 19, k + 0, IceikaBlockHelper.IceLeaves.blockID);
        world.setBlock(i + 5, j + 19, k + 1, IceikaBlockHelper.IceLeaves.blockID);
        world.setBlock(i + 5, j + 19, k + 2, IceikaBlockHelper.IceLeaves.blockID);
        world.setBlock(i + 5, j + 19, k + 3, IceikaBlockHelper.IceLeaves.blockID);
        world.setBlock(i + 5, j + 19, k + 4, IceikaBlockHelper.IceLeaves.blockID);
        world.setBlock(i + 5, j + 19, k + 5, IceikaBlockHelper.IceLeaves.blockID);
        world.setBlock(i + 5, j + 20, k + 0, 0);
        world.setBlock(i + 5, j + 20, k + 1, 0);
        world.setBlock(i + 5, j + 20, k + 2, 0);
        world.setBlock(i + 5, j + 20, k + 3, 0);
        world.setBlock(i + 5, j + 20, k + 4, 0);
        world.setBlock(i + 5, j + 20, k + 5, 0);
        world.setBlock(i + 5, j + 21, k + 0, 0);
        world.setBlock(i + 5, j + 21, k + 1, 0);
        world.setBlock(i + 5, j + 21, k + 2, 0);
        world.setBlock(i + 5, j + 21, k + 3, 0);
        world.setBlock(i + 5, j + 21, k + 4, 0);
        world.setBlock(i + 5, j + 21, k + 5, 0);
        world.setBlock(i + 5, j + 22, k + 0, IceikaBlockHelper.IceLeaves.blockID);
        world.setBlock(i + 5, j + 22, k + 1, IceikaBlockHelper.IceLeaves.blockID);
        world.setBlock(i + 5, j + 22, k + 2, IceikaBlockHelper.IceLeaves.blockID);
        world.setBlock(i + 5, j + 22, k + 3, IceikaBlockHelper.IceLeaves.blockID);
        world.setBlock(i + 5, j + 22, k + 4, IceikaBlockHelper.IceLeaves.blockID);
        world.setBlock(i + 5, j + 22, k + 5, IceikaBlockHelper.IceLeaves.blockID);
        world.setBlock(i + 5, j + 23, k + 0, 0);
        world.setBlock(i + 5, j + 23, k + 1, 0);
        world.setBlock(i + 5, j + 23, k + 2, 0);
        world.setBlock(i + 5, j + 23, k + 3, 0);
        world.setBlock(i + 5, j + 23, k + 4, 0);
        world.setBlock(i + 5, j + 23, k + 5, 0);
        world.setBlock(i + 5, j + 24, k + 0, IceikaBlockHelper.IceLeaves.blockID);
        world.setBlock(i + 5, j + 24, k + 1, IceikaBlockHelper.IceLeaves.blockID);
        world.setBlock(i + 5, j + 24, k + 2, IceikaBlockHelper.IceLeaves.blockID);
        world.setBlock(i + 5, j + 24, k + 3, IceikaBlockHelper.IceLeaves.blockID);
        world.setBlock(i + 5, j + 24, k + 4, IceikaBlockHelper.IceLeaves.blockID);
        world.setBlock(i + 5, j + 24, k + 5, IceikaBlockHelper.IceLeaves.blockID);
        world.setBlock(i + 5, j + 25, k + 0, 0);
        world.setBlock(i + 5, j + 25, k + 1, 0);
        world.setBlock(i + 5, j + 25, k + 2, 0);
        world.setBlock(i + 5, j + 25, k + 3, 0);
        world.setBlock(i + 5, j + 25, k + 4, 0);
        world.setBlock(i + 5, j + 25, k + 5, 0);
        world.setBlock(i + 5, j + 26, k + 0, 0);
        world.setBlock(i + 5, j + 26, k + 1, 0);
        world.setBlock(i + 5, j + 26, k + 2, 0);
        world.setBlock(i + 5, j + 26, k + 3, 0);
        world.setBlock(i + 5, j + 26, k + 4, 0);
        world.setBlock(i + 5, j + 26, k + 5, 0);

        return true;
    }
}